Workbook
Name Hallo: Annahmen!$K$10:$K$10
Name Startjahr: Annahmen!$B$5:$B$5

Sheet Annahmen
A2: ANNAHMEN: | F2: Statisches Eingabefeld
A3: Finanz- und Liquiditätsplanung | F3: Variables Eingabefeld
F4: Verknüpfung mit grünes Feld
A5: Startjahr | B5: 2025 | G5: Ausgangsposition | I5: Veränderungen
I6: Folgejahr
A7: Variable: | B7: Investitionskredit | D7: Ratenkredit | G7: 60000
A8: die unten | B8: Betriebsmittelkredit | D8: Ratenkredit | I8: 90000
A9: orange | B9: mtl. Gehaltserhöhung ab Folgejahr für Informatiker:innen | I9: 1000
A10: hinterlegten | B10: Kapazitätsauslastung | G10: 0.9 | I10: 0.9
A11: Felder | B11: Netto-Stundensatz beim Kunden | G11: 80 | I11: 100
A12: nehmen | B12: Anzahl Krankheitstage pro Informatiker:in | G12: 11 | I12: 11
A13: hier auf Bezug | B13: Weitere Investitionen | D13: Server im Folgejahr | I13: 30000
A15: Kredit | B15: aktuell
B16: Investitionskredit | C16: =$G$7 -> 60000
B17: Zinsatz p.a. | C17: 0.05
B18: Laufzeit | C18: 6
B19: Rate monatlich | C19: =C16/C18/12 -> 833.33333
B20: Betriebsmittelkredit | C20: =$G$8 -> 0
C21: =C17 -> 0.05
B22: Laufzeit | C22: =C18 -> 6
B23: Rate monatlich | C23: =IF(C20=0,0,C20/C22/12) -> 0
B25: zur Vereinfachung werden hier nur Bankkredite und keine Anultitätsdahrlen verwendet
A27: Steuersatz für KöSt./GewSt. | D27: 0.31925
K28: Veränderung | L28: verechenbare
A29: Wer erbringt die mit dem Kunden verechenbare Leistung? ==> gesucht sind die jährlich verechenbaren Stunden pro Vollzeit Informatiker:in | K29: Krankheitstage | L29: Stunden
A30: Ausgangspunkt | C30: 52 | D30: Wochen | E30: 5 | F30: Tage | G30: 8 | H30: Stunden | I30: =(C30*E30*G30) -> 2080 | L30: =I30 -> 2080
B31: Feiertage | E31: 11 | G31: 8 | I31: =-(E31*G31) -> -88 | L31: =I31 -> -88
B32: Urlaub | E32: 30 | G32: 8 | I32: =-(E32*G32) -> -240 | L32: =I32 -> -240
B33: Krankheit etc. | E33: =$G$12 -> 11 | G33: 8 | I33: =-(E33*G33) -> -88 | K33: =$I$12 -> 11 | L33: =-(G33*K33) -> -88
A34: verfügbare Stunden / Informatiker | I34: =SUM(I30:I33) -> 1664 | L34: =SUM(L30:L33) -> 1664
A35: nicht verreschenbare Stunden (E-Mails, Sitzungen, Telefonate, Recherche, Fehlerbehebung, etc.) | H35: 0.198718 | I35: =-(H35*I34) -> -330.66675 | L35: =-(H35*L34) -> -330.66675
A37: Verreschenbare Stunden | C37: 1 | D37: Kapazität | H37: Stunden p.a. | I37: =SUM(I34:I35) -> 1333.3332 | K37: Stunden p.a. | L37: =SUM(L34:L35) -> 1333.3332
E39: 2025 | F39: 2026 | H39: jan | I39: feb | J39: mar | K39: apr | L39: may | M39: jun | N39: jul | O39: aug | P39: sep | Q39: oct | R39: nov | S39: dec
A40: Umsatz
B41: Stundensatz | E41: =$G$11 -> 80 | F41: =$I$11 -> 100
B42: verrechnbare Stunden | E42: =I37 -> 1333.3332 | F42: =L37 -> 1333.3332
B43: Auslastung | E43: =$G$10 -> 0.9 | F43: =$I$10 -> 0.9
B44: geplante Auslastung | E44: =E42*E43 -> 1199.9999 | F44: =F42*F43 -> 1199.9999
B45: Anzahl Informatiker:in | E45: 15 | F45: 15
B46: Jahresumsatz | E46: =E41*E44*E45 -> 1439999.9 | F46: =F41*F44*F45 -> 1799999.9
...

Sheet GuV und Liquidität
O1: Gesamt | AB1: Gesamt
A2: (in Euro) | C2: Jan | D2: Feb | E2: Mar | F2: Apr | G2: May | H2: Jun | I2: Jul | J2: Aug | K2: Sep | L2: Oct | M2: Nov | N2: Dec | O2: 2025 | P2: Jan | Q2: Feb | R2: Mar | S2: Apr | T2: May | U2: Jun | V2: Jul | W2: Aug | X2: Sep | Y2: Oct | Z2: Nov | AA2: Dec | AB2: 2026
A3: Gewinn- und Verlustrechnung
A4: Umsatzerlöse netto | C4: =Umsatz!B6 -> 71999.995 | D4: =Umsatz!C6 -> 143999.99 | E4: =Umsatz!D6 -> 143999.99 | F4: =Umsatz!E6 -> 115199.99 | G4: =Umsatz!F6 -> 71999.995 | H4: =Umsatz!G6 -> 143999.99 | I4: =Umsatz!H6 -> 71999.995 | J4: =Umsatz!I6 -> 71999.995 | ... AB4: =Umsatz!AA6 -> 1799999.9
A5: Betriebliche Aufwendungen
B6: Personal | C6: =Personal!G21 -> 103333.32 | D6: =Personal!H21 -> 103333.32 | E6: =Personal!I21 -> 103333.32 | F6: =Personal!J21 -> 103333.32 | G6: =Personal!K21 -> 103333.32 | H6: =Personal!L21 -> 103333.32 | I6: =Personal!M21 -> 103333.32 | J6: =Personal!N21 -> 103333.32 | ... AB6: =Personal!AF21 -> 1459598.4
B7: Miete | C7: =Aufwand!B5 -> 3750 | D7: =Aufwand!C5 -> 3750 | E7: =Aufwand!D5 -> 3750 | F7: =Aufwand!E5 -> 3750 | G7: =Aufwand!F5 -> 3750 | H7: =Aufwand!G5 -> 3750 | I7: =Aufwand!H5 -> 3750 | J7: =Aufwand!I5 -> 3750 | ... AB7: =Aufwand!AA5 -> 45000
B8: so. Aufwand | C8: =Aufwand!B6 -> 7300 | D8: =Aufwand!C6 -> 6100 | E8: =Aufwand!D6 -> 7000 | F8: =Aufwand!E6 -> 6400 | G8: =Aufwand!F6 -> 23700 | H8: =Aufwand!G6 -> 6200 | I8: =Aufwand!H6 -> 7200 | J8: =Aufwand!I6 -> 6100 | ... AB8: =Aufwand!AA6 -> 100000
B9: Gesamt - Fixkosten | C9: =SUM(C6:C8) -> 114383.32 | D9: =SUM(D6:D8) -> 113183.32 | E9: =SUM(E6:E8) -> 114083.32 | F9: =SUM(F6:F8) -> 113483.32 | G9: =SUM(G6:G8) -> 130783.32 | H9: =SUM(H6:H8) -> 113283.32 | I9: =SUM(I6:I8) -> 114283.32 | J9: =SUM(J6:J8) -> 113183.32 | ... AB9: =SUM(AB6:AB8) -> 1604598.4
B10: Finanzierungskosten (Zinsen etc.) | C10: =Kredit!C19 -> 250 | D10: =Kredit!D19 -> 246.52778 | E10: =Kredit!E19 -> 243.05556 | F10: =Kredit!F19 -> 239.58333 | G10: =Kredit!G19 -> 236.11111 | H10: =Kredit!H19 -> 232.63889 | I10: =Kredit!I19 -> 229.16667 | J10: =Kredit!J19 -> 225.69444 | ... AB10: =Kredit!AB19 -> 6427.0833
B11: Abschreibungen | C11: =Investitionen!E19 -> 1500 | D11: =Investitionen!F19 -> 1500 | E11: =Investitionen!G19 -> 1500 | F11: =Investitionen!H19 -> 1500 | G11: =Investitionen!I19 -> 1500 | H11: =Investitionen!J19 -> 1500 | I11: =Investitionen!K19 -> 1500 | J11: =Investitionen!L19 -> 1500 | ... AB11: =Investitionen!AD19 -> 24000
A12: Betriebliche Aufwendungen netto | C12: =SUM(C9:C11) -> 116133.32 | D12: =SUM(D9:D11) -> 114929.85 | E12: =SUM(E9:E11) -> 115826.38 | F12: =SUM(F9:F11) -> 115222.91 | G12: =SUM(G9:G11) -> 132519.43 | H12: =SUM(H9:H11) -> 115015.96 | I12: =SUM(I9:I11) -> 116012.49 | J12: =SUM(J9:J11) -> 114909.02 | ... AB12: =SUM(AB9:AB11) -> 1635025.5
A14: Jahresüberschuss/Jahresfehlbetrag vor Steuern | C14: =C4-C12 -> -44133.327 | D14: =D4-D12 -> 29070.141 | E14: =E4-E12 -> 28173.613 | F14: =F4-F12 -> -22.913106 | G14: =G4-G12 -> -60519.438 | H14: =H4-H12 -> 28984.029 | I14: =I4-I12 -> -44012.494 | J14: =J4-J12 -> -42909.021 | ... AB14: =AB4-AB12 -> 164974.37
A15: GewSt. + KöSt. + Soli laufendes Jahr | N15: =IF(O14>0,-O14*Annahmen!D27,0) -> -10927.674 | O15: =SUM(C15:N15) -> -10927.674 | AA15: =IF(AB14>0,-AB14*Annahmen!D27,0) -> -52668.068 | AB15: =SUM(P15:AA15) -> -52668.068
A16: Jahresüberschuss/Jahresfehlbetrag nach Steuern | C16: =SUM(C14:C15) -> -44133.327 | D16: =SUM(D14:D15) -> 29070.141 | E16: =SUM(E14:E15) -> 28173.613 | F16: =SUM(F14:F15) -> -22.913106 | G16: =SUM(G14:G15) -> -60519.438 | H16: =SUM(H14:H15) -> 28984.029 | I16: =SUM(I14:I15) -> -44012.494 | J16: =SUM(J14:J15) -> -42909.021 | ... AB16: =SUM(AB14:AB15) -> 112306.3
A17: Liqitätsrechnung
A18: Jahresabschluss/Jahresfehlbetrag vor Steuern | C18: =C14 -> -44133.327 | D18: =D14 -> 29070.141 | E18: =E14 -> 28173.613 | F18: =F14 -> -22.913106 | G18: =G14 -> -60519.438 | H18: =H14 -> 28984.029 | I18: =I14 -> -44012.494 | J18: =J14 -> -42909.021 | ... AB18: =AB14 -> 164974.37
B19: Steuervoraus-/nachzahlung Köst/GewSt/Soli | E19: =$N$15/4 -> -2731.9185 | H19: =$N$15/4 -> -2731.9185 | K19: =$N$15/4 -> -2731.9185 | N19: =$N$15/4 -> -2731.9185 | O19: =N15 -> -10927.674 | R19: =$AB$15/4 -> -13167.017 | U19: =$AB$15/4 -> -13167.017 | X19: =$AB$15/4 -> -13167.017 | AA19: =$AB$15/4 -> -13167.017 | AB19: =AB15 -> -52668.068
B20: Abschreibungen | C20: =Investitionen!E19 -> 1500 | D20: =Investitionen!F19 -> 1500 | E20: =Investitionen!G19 -> 1500 | F20: =Investitionen!H19 -> 1500 | G20: =Investitionen!I19 -> 1500 | H20: =Investitionen!J19 -> 1500 | I20: =Investitionen!K19 -> 1500 | J20: =Investitionen!L19 -> 1500 | ... AB20: =Investitionen!AD19 -> 24000
A21: Cashflow aus der laufenden Geschäftstätigkeit | C21: =SUM(C18:C20) -> -42633.327 | D21: =SUM(D18:D20) -> 30570.141 | E21: =SUM(E18:E20) -> 26941.694 | F21: =SUM(F18:F20) -> 1477.0869 | G21: =SUM(G18:G20) -> -59019.438 | H21: =SUM(H18:H20) -> 27752.111 | I21: =SUM(I18:I20) -> -42512.494 | J21: =SUM(J18:J20) -> -41409.021 | ... AB21: =SUM(AB18:AB20) -> 136306.3
B22: Investitionen incl. Kaution | C22: =-Investitionen!E20 -> -104000 | D22: =-Investitionen!F20 -> 0 | E22: =-Investitionen!G20 -> 0 | F22: =-Investitionen!H20 -> 0 | G22: =-Investitionen!I20 -> 0 | H22: =-Investitionen!J20 -> 0 | I22: =-Investitionen!K20 -> 0 | J22: =-Investitionen!L20 -> 0 | ... AB22: =-Investitionen!AD20 -> -30000
A23: Cashflow aus Investitionstätigkeiten | C23: =SUM(C22) -> -104000 | D23: =SUM(D22) -> 0 | E23: =SUM(E22) -> 0 | F23: =SUM(F22) -> 0 | G23: =SUM(G22) -> 0 | H23: =SUM(H22) -> 0 | I23: =SUM(I22) -> 0 | J23: =SUM(J22) -> 0 | ... AB23: =SUM(AB22) -> -30000
B24: Kreditaufnahme | C24: =SUM(Annahmen!G7:G8) -> 60000 | D24: 0 | E24: 0 | F24: 0 | G24: 0 | H24: 0 | I24: 0 | J24: 0 | K24: 0 | L24: 0 | M24: 0 | N24: 0 | O24: =SUM('GuV und Liquidität'!C24:N24) -> 60000 | P24: =SUM(Annahmen!I7:I8) -> 90000 | Q24: 0 | R24: 0 | S24: 0 | T24: 0 | U24: 0 | V24: 0 | W24: 0 | X24: 0 | Y24: 0 | Z24: 0 | AA24: 0 | AB24: =SUM(P24:AA24) -> 90000
B25: Kredittilgung | C25: =-Kredit!C21 -> -833.33333 | D25: =-Kredit!D21 -> -833.33333 | E25: =-Kredit!E21 -> -833.33333 | F25: =-Kredit!F21 -> -833.33333 | G25: =-Kredit!G21 -> -833.33333 | H25: =-Kredit!H21 -> -833.33333 | I25: =-Kredit!I21 -> -833.33333 | J25: =-Kredit!J21 -> -833.33333 | ... AB25: =-Kredit!AB21 -> -25000
A26: Cashflow aus Finanzierungstätigkeiten | C26: =SUM(C24:C25) -> 59166.667 | D26: =SUM(D24:D25) -> -833.33333 | E26: =SUM(E24:E25) -> -833.33333 | F26: =SUM(F24:F25) -> -833.33333 | G26: =SUM(G24:G25) -> -833.33333 | H26: =SUM(H24:H25) -> -833.33333 | I26: =SUM(I24:I25) -> -833.33333 | J26: =SUM(J24:J25) -> -833.33333 | ... AB26: =SUM(AB24:AB25) -> 65000
B27: Monatliche Kassenveränderungen | C27: =C26+C23+C21 -> -87466.66 | D27: =D21+D23+D26 -> 29736.807 | E27: =E21+E23+E26 -> 26108.361 | F27: =F21+F23+F26 -> 643.75356 | G27: =G21+G23+G26 -> -59852.771 | H27: =H21+H23+H26 -> 26918.778 | I27: =I21+I23+I26 -> -43345.827 | J27: =J21+J23+J26 -> -42242.355 | K27: =K21+K23+K26 -> 94629.19 | ... AB27: =AB21+AB23+AB26 -> 171306.3
A28: Über-/ Unterdeckung komuliert ohne Vorjahr | C28: =C27 -> -87466.66 | D28: =C28+D27 -> -57729.853 | E28: =D28+E27 -> -31621.492 | F28: =E28+F27 -> -30977.738 | G28: =F28+G27 -> -90830.51 | H28: =G28+H27 -> -63911.732 | I28: =H28+I27 -> -107257.56 | J28: =I28+J27 -> -149499.91 | K28: =J28+K27 -> -54870.724 | ... N28: =M28+N27 -> -12698.468 | O28: =N28 -> -12698.468 | P28: =P27 -> 14650.125 | Q28: =P28+Q27 -> 60508.925 | R28: =Q28+R27 -> 92309.389 | S28: =R28+S27 -> 101885.55 | T28: =S28+T27 -> 40170.399 | U28: =T28+U27 -> 72796.904 | V28: =U28+V27 -> 27599.113 | W28: =V28+W27 -> -16489.998 | X28: =W28+X27 -> 101862.54 | ... AA28: =Z28+AA27 -> 171306.3 | AB28: =AA28 -> 171306.3
B29: Kasenbestand Vorjahr | C29: =Annahmen!D82 -> 100000 | O29: =SUM(C29:N29) -> 100000 | P29: =O30 -> 87301.532 | AB29: =SUM(P29:AA29) -> 87301.532
A30: Liqität mit Kasse Vorjahr | C30: =$C$29+C28 -> 12533.34 | D30: =$C$29+D28 -> 42270.147 | E30: =$C$29+E28 -> 68378.508 | F30: =$C$29+F28 -> 69022.262 | G30: =$C$29+G28 -> 9169.4901 | H30: =$C$29+H28 -> 36088.268 | I30: =$C$29+I28 -> -7257.5593 | J30: =$C$29+J28 -> -49499.914 | ... N30: =$C$29+N28 -> 87301.532 | O30: =O29+O28 -> 87301.532 | P30: =$P$29+P28 -> 101951.66 | Q30: =$P$29+Q28 -> 147810.46 | R30: =$P$29+R28 -> 179610.92 | S30: =$P$29+S28 -> 189187.08 | T30: =$P$29+T28 -> 127471.93 | U30: =$P$29+U28 -> 160098.44 | V30: =$P$29+V28 -> 114900.64 | W30: =$P$29+W28 -> 70811.534 | ... AA30: =$P$29+AA28 -> 258607.84 | AB30: =AB28+AB29 -> 258607.84

Sheet Bilanz
A1: Ausgangslage | C1: 2024 | D1: 2025 | E1: 2026
C2: 12 | D2: 12 | E2: 12
A3: Anlagevermögen
B4: PCs, Drucker, Laptops | C4: 0 | D4: =Investitionen!B13-Investitionen!Q13 -> 26000 | E4: =Investitionen!B13-Investitionen!Q13-Investitionen!AD13 -> 13000
B5: Server | C5: 0 | D5: 0 | E5: =Investitionen!B14-Investitionen!AD14 -> 24000
B6: Büroausstattung | C6: 0 | D6: =Investitionen!B7-Investitionen!Q7 -> 60000 | E6: =Investitionen!B7-Investitionen!Q7-Investitionen!AD7 -> 55000
A7: Anlagevermögen | C7: =SUM(C4:C6) -> 0 | D7: =SUM(D4:D6) -> 86000 | E7: =SUM(E4:E6) -> 92000
A9: Umlaufvermögen
B10: Forderungen aus Lieferung & Leistung | C10: =Annahmen!D87 -> 0 | D10: 0 | E10: 0
B11: Kassenbestand | C11: =Annahmen!D82 -> 100000 | D11: ='GuV und Liquidität'!O30 -> 87301.532 | E11: ='GuV und Liquidität'!AB30 -> 258607.84
A12: Umlaufvermögen | C12: =SUM(C9:C11) -> 100000 | D12: =SUM(D9:D11) -> 87301.532 | E12: =SUM(E9:E11) -> 258607.84
A13: Bilanzsumme | C13: =SUM(C7+C12) -> 100000 | D13: =SUM(D7+D12) -> 173301.53 | E13: =SUM(E7+E12) -> 350607.84
A15: Eigenkapital
B16: Stammkapital | C16: =Annahmen!D84 -> 50000 | D16: =Annahmen!D84 -> 50000 | E16: =Annahmen!D84 -> 50000
B17: Gewinnvortrag | C17: =Annahmen!D85 -> 30000 | D17: =C17+C18 -> 50000 | E17: =D17+D18 -> 73301.532
B18: Jahresüberschuss | C18: =Annahmen!D86 -> 20000 | D18: ='GuV und Liquidität'!O16 -> 23301.532 | E18: ='GuV und Liquidität'!AB16 -> 112306.3
A19: Eigenkapital | C19: =SUM(C16:C18) -> 100000 | D19: =SUM(D16:D18) -> 123301.53 | E19: =SUM(E16:E18) -> 235607.84
A21: Langfristige Verbindlichkeiten | C21: 0 | D21: =Kredit!O23 -> 50000 | E21: =Kredit!AB23 -> 115000
A22: Kurzfristige Verbindlichkeiten | C22: 0 | D22: 0 | E22: 0
A23: Bilanzsumme | C23: =SUM(C19+C21+C22) -> 100000 | D23: =SUM(D19+D21+D22) -> 173301.53 | E23: =SUM(E19+E21+E22) -> 350607.84

Sheet Umsatz
N2: Gesamt | AA2: Gesamt
B3: Jan | C3: Feb | D3: Mrz | E3: Apr | F3: Mai | G3: Jun | H3: Jul | I3: Aug | J3: Sep | K3: Okt | L3: Nov | M3: Dez | N3: 2025 | O3: Jan | P3: Feb | Q3: Mrz | R3: Apr | S3: Mai | T3: Jun | U3: Jul | V3: Aug | W3: Sep | X3: Okt | Y3: Nov | Z3: Dez | AA3: 2026
A4: Umsatzverteilung | B4: 0.05 | C4: 0.1 | D4: 0.1 | E4: 0.08 | F4: 0.05 | G4: 0.1 | H4: 0.05 | I4: 0.05 | J4: 0.15 | K4: 0.1 | L4: 0.08 | M4: 0.09 | O4: 0.05 | P4: 0.1 | Q4: 0.1 | R4: 0.08 | S4: 0.05 | T4: 0.1 | U4: 0.05 | V4: 0.05 | W4: 0.15 | X4: 0.1 | Y4: 0.08 | Z4: 0.09
A6: Umsatzerlös Gesamt | B6: =$N$6*B4 -> 71999.995 | C6: =$N$6*C4 -> 143999.99 | D6: =$N$6*D4 -> 143999.99 | E6: =$N$6*E4 -> 115199.99 | F6: =$N$6*F4 -> 71999.995 | G6: =$N$6*G4 -> 143999.99 | H6: =$N$6*H4 -> 71999.995 | I6: =$N$6*I4 -> 71999.995 | ... M6: =$N$6*M4 -> 129599.99 | N6: =Annahmen!$E$46 -> 1439999.9 | O6: =$AA$6*O4 -> 89999.994 | P6: =$AA$6*P4 -> 179999.99 | Q6: =$AA$6*Q4 -> 179999.99 | R6: =$AA$6*R4 -> 143999.99 | S6: =$AA$6*S4 -> 89999.994 | T6: =$AA$6*T4 -> 179999.99 | U6: =$AA$6*U4 -> 89999.994 | V6: =$AA$6*V4 -> 89999.994 | ... Z6: =$AA$6*Z4 -> 161999.99 | AA6: =Annahmen!$F$46 -> 1799999.9
P8: GESAMT

Sheet Personal
B1: (in Euro)
E2: Bruttogehalt beginn | G2: =2025 -> 2025 | S2: Gesamt | AF2: Gesamt
G3: 45658 | H3: 45689 | I3: 45717 | J3: 45748 | K3: 45778 | L3: 45809 | M3: 45839 | N3: 45870 | O3: 45901 | P3: 45931 | Q3: 45962 | R3: 45992 | S3: 2025 | T3: Jan | U3: Feb | V3: Mar | W3: Apr | X3: May | Y3: Jun | Z3: Jul | AA3: Aug | AB3: Sep | AC3: Oct | AD3: Nov | AE3: Dec | AF3: 2026
A4: Bestand
A6: 1 | B6: Geschäftsfürhrung | C6: =Annahmen!E49 -> 40 | D6: =Annahmen!D49 -> 7000 | E6: =Annahmen!G49 -> 7000 | F6: 45658 | G6: =$E$6 -> 7000 | H6: =$E$6 -> 7000 | I6: =$E$6 -> 7000 | J6: =$E$6 -> 7000 | K6: =$E$6 -> 7000 | L6: =$E$6 -> 7000 | M6: =$E$6 -> 7000 | N6: =$E$6 -> 7000 | ... R6: =$E$6 -> 7000 | S6: =SUM(G6:R6) -> 84000 | T6: =$E$6 -> 7000 | U6: =$E$6 -> 7000 | V6: =$E$6 -> 7000 | W6: =$E$6 -> 7000 | X6: =$E$6 -> 7000 | Y6: =$E$6 -> 7000 | Z6: =$E$6 -> 7000 | AA6: =$E$6 -> 7000 | ... AE6: =$E$6 -> 7000 | AF6: =SUM(T6:AE6) -> 84000
A7: =Annahmen!C50 -> 1 | B7: Buchhaltung | C7: =Annahmen!E50 -> 40 | D7: =Annahmen!D50 -> 3300 | E7: =Annahmen!G50 -> 3300 | F7: 45658 | G7: =$E$7 -> 3300 | H7: =$E$7 -> 3300 | I7: =$E$7 -> 3300 | J7: =$E$7 -> 3300 | K7: =$E$7 -> 3300 | L7: =$E$7 -> 3300 | M7: =$E$7 -> 3300 | N7: =$E$7 -> 3300 | ... R7: =$E$7 -> 3300 | S7: =SUM(G7:R7) -> 39600 | T7: =$E$7 -> 3300 | U7: =$E$7 -> 3300 | V7: =$E$7 -> 3300 | W7: =$E$7 -> 3300 | X7: =$E$7 -> 3300 | Y7: =$E$7 -> 3300 | Z7: =$E$7 -> 3300 | AA7: =$E$7 -> 3300 | ... AE7: =$E$7 -> 3300 | AF7: =SUM(T7:AE7) -> 39600
A8: =Annahmen!C51 -> 2 | B8: Assistenz | C8: =Annahmen!E51 -> 40 | D8: =Annahmen!D51 -> 3300 | E8: =Annahmen!G51 -> 6600 | F8: 45658 | G8: =$E$8 -> 6600 | H8: =$E$8 -> 6600 | I8: =$E$8 -> 6600 | J8: =$E$8 -> 6600 | K8: =$E$8 -> 6600 | L8: =$E$8 -> 6600 | M8: =$E$8 -> 6600 | N8: =$E$8 -> 6600 | ... R8: =$E$8 -> 6600 | S8: =SUM(G8:R8) -> 79200 | T8: =$E$8 -> 6600 | U8: =$E$8 -> 6600 | V8: =$E$8 -> 6600 | W8: =$E$8 -> 6600 | X8: =$E$8 -> 6600 | Y8: =$E$8 -> 6600 | Z8: =$E$8 -> 6600 | AA8: =$E$8 -> 6600 | ... AE8: =$E$8 -> 6600 | AF8: =SUM(T8:AE8) -> 79200
A9: =Annahmen!C52 -> 1 | B9: Techniker | C9: =Annahmen!E52 -> 40 | D9: =Annahmen!D52 -> 3300 | E9: =Annahmen!G52 -> 3300 | F9: 45658 | G9: =$E$9 -> 3300 | H9: =$E$9 -> 3300 | I9: =$E$9 -> 3300 | J9: =$E$9 -> 3300 | K9: =$E$9 -> 3300 | L9: =$E$9 -> 3300 | M9: =$E$9 -> 3300 | N9: =$E$9 -> 3300 | ... R9: =$E$9 -> 3300 | S9: =SUM(G9:R9) -> 39600 | T9: =$E$9 -> 3300 | U9: =$E$9 -> 3300 | V9: =$E$9 -> 3300 | W9: =$E$9 -> 3300 | X9: =$E$9 -> 3300 | Y9: =$E$9 -> 3300 | Z9: =$E$9 -> 3300 | AA9: =$E$9 -> 3300 | ... AE9: =$E$9 -> 3300 | AF9: =SUM(T9:AE9) -> 39600
A10: =Annahmen!C54 -> 15 | B10: Informatiker | C10: =Annahmen!E53 -> 40 | D10: =Annahmen!D53 -> 4300 | E10: =Annahmen!G53 -> 64500 | F10: 45658 | G10: =$E$10 -> 64500 | H10: =$E$10 -> 64500 | I10: =$E$10 -> 64500 | J10: =$E$10 -> 64500 | K10: =$E$10 -> 64500 | L10: =$E$10 -> 64500 | M10: =$E$10 -> 64500 | N10: =$E$10 -> 64500 | ... R10: =$E$10 -> 64500 | S10: =SUM(G10:R10) -> 774000 | T10: =$E$10+$E$15 -> 79500 | U10: =$E$10+$E$15 -> 79500 | V10: =$E$10+$E$15 -> 79500 | W10: =$E$10+$E$15 -> 79500 | X10: =$E$10+$E$15 -> 79500 | Y10: =$E$10+$E$15 -> 79500 | Z10: =$E$10+$E$15 -> 79500 | AA10: =$E$10+$E$15 -> 79500 | ... AE10: =$E$10+$E$15 -> 79500 | AF10: =SUM(T10:AE10) -> 954000
B12: Gesamt - Bestand | G12: =SUM(G6:G10) -> 84700 | H12: =SUM(H6:H10) -> 84700 | I12: =SUM(I6:I10) -> 84700 | J12: =SUM(J6:J10) -> 84700 | K12: =SUM(K6:K10) -> 84700 | L12: =SUM(L6:L10) -> 84700 | M12: =SUM(M6:M10) -> 84700 | N12: =SUM(N6:N10) -> 84700 | ... AF12: =SUM(AF6:AF10) -> 1196400
A13: Neu
A15: 15 | B15: Gehaltserhöhung | D15: =Annahmen!D54 -> 1000 | E15: =Annahmen!H54 -> 15000 | F15: 46023
B17: Gesamt - Neu
A18: Zusammenfassung
B19: Gesamt(ohne Sozialversicherung) | G19: =G12 -> 84700 | H19: =H12 -> 84700 | I19: =I12 -> 84700 | J19: =J12 -> 84700 | K19: =K12 -> 84700 | L19: =L12 -> 84700 | M19: =M12 -> 84700 | N19: =N12 -> 84700 | ... AF19: =AF12 -> 1196400
B20: Sozialversicherung | C20: =Annahmen!I48 -> 0.219992 | G20: =G19*$C$20 -> 18633.322 | H20: =H19*$C$20 -> 18633.322 | I20: =I19*$C$20 -> 18633.322 | J20: =J19*$C$20 -> 18633.322 | K20: =K19*$C$20 -> 18633.322 | L20: =L19*$C$20 -> 18633.322 | M20: =M19*$C$20 -> 18633.322 | N20: =N19*$C$20 -> 18633.322 | ... AF20: =AF19*$C$20 -> 263198.43
B21: Gesamt Personal | G21: =SUM(G19:G20) -> 103333.32 | H21: =SUM(H19:H20) -> 103333.32 | I21: =SUM(I19:I20) -> 103333.32 | J21: =SUM(J19:J20) -> 103333.32 | K21: =SUM(K19:K20) -> 103333.32 | L21: =SUM(L19:L20) -> 103333.32 | M21: =SUM(M19:M20) -> 103333.32 | N21: =SUM(N19:N20) -> 103333.32 | ... AF21: =SUM(AF19:AF20) -> 1459598.4

Sheet Aufwand
N1: Gesamt | AA1: Gesamt
A2: Nettobeträge (in Euro) | B2: Jan | C2: Feb | D2: Mrz | E2: Apr | F2: Mai | G2: Jun | H2: Jul | I2: Aug | J2: Sep | K2: Okt | L2: Nov | M2: Dez | N2: 2025 | O2: Jan | P2: Feb | Q2: Mrz | R2: Apr | S2: Mai | T2: Jun | U2: Jul | V2: Aug | W2: Sep | X2: Okt | Y2: Nov | Z2: Dez | AA2: 2026
A4: Verteilung so. Aufwand | B4: =Annahmen!H60 -> 0.073 | C4: =Annahmen!I60 -> 0.061 | D4: =Annahmen!J60 -> 0.07 | E4: =Annahmen!K60 -> 0.064 | F4: =Annahmen!L60 -> 0.237 | G4: =Annahmen!M60 -> 0.062 | H4: =Annahmen!N60 -> 0.072 | I4: =Annahmen!O60 -> 0.061 | ... M4: =Annahmen!S60 -> 0.061 | N4: =SUM(B4:M4) -> 1 | O4: =Annahmen!H60 -> 0.073 | P4: =Annahmen!I60 -> 0.061 | Q4: =Annahmen!J60 -> 0.07 | R4: =Annahmen!K60 -> 0.064 | S4: =Annahmen!L60 -> 0.237 | T4: =Annahmen!M60 -> 0.062 | U4: =Annahmen!N60 -> 0.072 | V4: =Annahmen!O60 -> 0.061 | ... Z4: =Annahmen!S60 -> 0.061 | AA4: =SUM(O4:Z4) -> 1
A5: Miete | B5: =$N$5/12 -> 3750 | C5: =$N$5/12 -> 3750 | D5: =$N$5/12 -> 3750 | E5: =$N$5/12 -> 3750 | F5: =$N$5/12 -> 3750 | G5: =$N$5/12 -> 3750 | H5: =$N$5/12 -> 3750 | I5: =$N$5/12 -> 3750 | ... M5: =$N$5/12 -> 3750 | N5: =Annahmen!E59 -> 45000 | O5: =$AA$5/12 -> 3750 | P5: =$AA$5/12 -> 3750 | Q5: =$AA$5/12 -> 3750 | R5: =$AA$5/12 -> 3750 | S5: =$AA$5/12 -> 3750 | T5: =$AA$5/12 -> 3750 | U5: =$AA$5/12 -> 3750 | V5: =$AA$5/12 -> 3750 | ... Z5: =$AA$5/12 -> 3750 | AA5: =Annahmen!E59 -> 45000
A6: so. Aufwand | B6: =Annahmen!H61 -> 7300 | C6: =Annahmen!I61 -> 6100 | D6: =Annahmen!J61 -> 7000 | E6: =Annahmen!K61 -> 6400 | F6: =Annahmen!L61 -> 23700 | G6: =Annahmen!M61 -> 6200 | H6: =Annahmen!N61 -> 7200 | I6: =Annahmen!O61 -> 6100 | ... M6: =Annahmen!S61 -> 6100 | N6: =Annahmen!E60 -> 100000 | O6: =Annahmen!H61 -> 7300 | P6: =Annahmen!I61 -> 6100 | Q6: =Annahmen!J61 -> 7000 | R6: =Annahmen!K61 -> 6400 | S6: =Annahmen!L61 -> 23700 | T6: =Annahmen!M61 -> 6200 | U6: =Annahmen!N61 -> 7200 | V6: =Annahmen!O61 -> 6100 | ... Z6: =Annahmen!S61 -> 6100 | AA6: =Annahmen!E60 -> 100000

Sheet Kredit
B1: Planung | C1: Jan | D1: Feb | E1: Mrz | F1: Apr | G1: Mai | H1: Jun | I1: Jul | J1: Aug | K1: Sep | L1: Okt | M1: Nov | N1: Dez | O1: Gesamt | P1: Jan | Q1: Feb | R1: Mrz | S1: Apr | T1: Mai | U1: Jun | V1: Jul | W1: Aug | X1: Sep | Y1: Okt | Z1: Nov | AA1: Dez | AB1: Gesamt | AC1: Jan | AD1: Feb | AE1: Mrz | AF1: Apr | AG1: Mai | AH1: Jun | AI1: Jul | AJ1: Aug | AK1: Sep | AL1: Okt | AM1: Nov | AN1: Dez | AO1: Gesamt | AP1: Jan | AQ1: Feb | AR1: Mrz | AS1: Apr | AT1: Mai | AU1: Jun | AV1: Jul | AW1: Aug | AX1: Sep | AY1: Okt | AZ1: Nov | BA1: Dez | BB1: Gesamt | BC1: Jan | BD1: Feb | BE1: Mrz | BF1: Apr | BG1: Mai | BH1: Jun | BI1: Jul | BJ1: Aug | BK1: Sep | BL1: Okt | BM1: Nov | BN1: Dez | BO1: Gesamt | BP1: Jan | BQ1: Feb | BR1: Mrz | BS1: Apr | BT1: Mai | BU1: Jun | BV1: Jul | BW1: Aug | BX1: Sep | BY1: Okt | BZ1: Nov | CA1: Dez | CB1: Gesamt
B2: Ausgaben | O2: 2025 | AB2: 2026 | AO2: 2027 | BB2: 2028 | BO2: 2029 | CB2: 2030
A4: Anuitätendahrlen 1
A5: Tilgung | B5: =B7/12/Annahmen!C18 -> 833.33333 | C5: =$B$5 -> 833.33333 | D5: =$B$5 -> 833.33333 | E5: =$B$5 -> 833.33333 | F5: =$B$5 -> 833.33333 | G5: =$B$5 -> 833.33333 | H5: =$B$5 -> 833.33333 | I5: =$B$5 -> 833.33333 | J5: =$B$5 -> 833.33333 | ... N5: =$B$5 -> 833.33333 | O5: =SUM(C5:N5) -> 10000 | P5: =$B$5 -> 833.33333 | Q5: =$B$5 -> 833.33333 | R5: =$B$5 -> 833.33333 | S5: =$B$5 -> 833.33333 | T5: =$B$5 -> 833.33333 | U5: =$B$5 -> 833.33333 | V5: =$B$5 -> 833.33333 | W5: =$B$5 -> 833.33333 | ... AA5: =$B$5 -> 833.33333 | AB5: =SUM(P5:AA5) -> 10000 | AC5: =$B$5 -> 833.33333 | AD5: =$B$5 -> 833.33333 | AE5: =$B$5 -> 833.33333 | AF5: =$B$5 -> 833.33333 | AG5: =$B$5 -> 833.33333 | AH5: =$B$5 -> 833.33333 | AI5: =$B$5 -> 833.33333 | AJ5: =$B$5 -> 833.33333 | ... AN5: =$B$5 -> 833.33333 | AO5: =SUM(AC5:AN5) -> 10000 | AP5: =$B$5 -> 833.33333 | AQ5: =$B$5 -> 833.33333 | AR5: =$B$5 -> 833.33333 | AS5: =$B$5 -> 833.33333 | AT5: =$B$5 -> 833.33333 | AU5: =$B$5 -> 833.33333 | AV5: =$B$5 -> 833.33333 | AW5: =$B$5 -> 833.33333 | ... BA5: =$B$5 -> 833.33333 | BB5: =SUM(AP5:BA5) -> 10000 | BC5: =$B$5 -> 833.33333 | BD5: =$B$5 -> 833.33333 | BE5: =$B$5 -> 833.33333 | BF5: =$B$5 -> 833.33333 | BG5: =$B$5 -> 833.33333 | BH5: =$B$5 -> 833.33333 | BI5: =$B$5 -> 833.33333 | BJ5: =$B$5 -> 833.33333 | ... BN5: =$B$5 -> 833.33333 | BO5: =SUM(BC5:BN5) -> 10000 | BP5: =$B$5 -> 833.33333 | BQ5: =$B$5 -> 833.33333 | BR5: =$B$5 -> 833.33333 | BS5: =$B$5 -> 833.33333 | BT5: =$B$5 -> 833.33333 | BU5: =$B$5 -> 833.33333 | BV5: =$B$5 -> 833.33333 | BW5: =$B$5 -> 833.33333 | ... CA5: =$B$5 -> 833.33333 | CB5: =SUM(BP5:CA5) -> 10000
A6: Zins | B6: =Annahmen!C17 -> 0.05 | C6: =B7*$B$6/12 -> 250 | D6: =C7*$B$6/12 -> 246.52778 | E6: =D7*$B$6/12 -> 243.05556 | F6: =E7*$B$6/12 -> 239.58333 | G6: =F7*$B$6/12 -> 236.11111 | H6: =G7*$B$6/12 -> 232.63889 | I6: =H7*$B$6/12 -> 229.16667 | J6: =I7*$B$6/12 -> 225.69444 | ... N6: =M7*$B$6/12 -> 211.80556 | O6: =SUM(C6:N6) -> 2770.8333 | P6: =O7*$B$6/12 -> 208.33333 | Q6: =P7*$B$6/12 -> 204.86111 | R6: =Q7*$B$6/12 -> 201.38889 | S6: =R7*$B$6/12 -> 197.91667 | T6: =S7*$B$6/12 -> 194.44444 | U6: =T7*$B$6/12 -> 190.97222 | V6: =U7*$B$6/12 -> 187.5 | W6: =V7*$B$6/12 -> 184.02778 | ... AA6: =Z7*$B$6/12 -> 170.13889 | AB6: =SUM(P6:AA6) -> 2270.8333 | AC6: =AB7*$B$6/12 -> 166.66667 | AD6: =AC7*$B$6/12 -> 163.19444 | AE6: =AD7*$B$6/12 -> 159.72222 | AF6: =AE7*$B$6/12 -> 156.25 | AG6: =AF7*$B$6/12 -> 152.77778 | AH6: =AG7*$B$6/12 -> 149.30556 | AI6: =AH7*$B$6/12 -> 145.83333 | AJ6: =AI7*$B$6/12 -> 142.36111 | ... AN6: =AM7*$B$6/12 -> 128.47222 | AO6: =SUM(AC6:AN6) -> 1770.8333 | AP6: =AO7*$B$6/12 -> 125 | AQ6: =AP7*$B$6/12 -> 121.52778 | AR6: =AQ7*$B$6/12 -> 118.05556 | AS6: =AR7*$B$6/12 -> 114.58333 | AT6: =AS7*$B$6/12 -> 111.11111 | AU6: =AT7*$B$6/12 -> 107.63889 | AV6: =AU7*$B$6/12 -> 104.16667 | AW6: =AV7*$B$6/12 -> 100.69444 | ... BA6: =AZ7*$B$6/12 -> 86.805556 | BB6: =SUM(AP6:BA6) -> 1270.8333 | BC6: =BB7*$B$6/12 -> 83.333333 | BD6: =BC7*$B$6/12 -> 79.861111 | BE6: =BD7*$B$6/12 -> 76.388889 | BF6: =BE7*$B$6/12 -> 72.916667 | BG6: =BF7*$B$6/12 -> 69.444444 | BH6: =BG7*$B$6/12 -> 65.972222 | BI6: =BH7*$B$6/12 -> 62.5 | BJ6: =BI7*$B$6/12 -> 59.027778 | ... BN6: =BM7*$B$6/12 -> 45.138889 | BO6: =SUM(BC6:BN6) -> 770.83333 | BP6: =BO7*$B$6/12 -> 41.666667 | BQ6: =BP7*$B$6/12 -> 38.194444 | BR6: =BQ7*$B$6/12 -> 34.722222 | BS6: =BR7*$B$6/12 -> 31.25 | BT6: =BS7*$B$6/12 -> 27.777778 | BU6: =BT7*$B$6/12 -> 24.305556 | BV6: =BU7*$B$6/12 -> 20.833333 | BW6: =BV7*$B$6/12 -> 17.361111 | ... CA6: =BZ7*$B$6/12 -> 3.4722222 | CB6: =SUM(BP6:CA6) -> 270.83333
A7: Restbetrag | B7: =Annahmen!C16 -> 60000 | C7: =B7-C5 -> 59166.667 | D7: =C7-D5 -> 58333.333 | E7: =D7-E5 -> 57500 | F7: =E7-F5 -> 56666.667 | G7: =F7-G5 -> 55833.333 | H7: =G7-H5 -> 55000 | I7: =H7-I5 -> 54166.667 | J7: =I7-J5 -> 53333.333 | ... N7: =M7-N5 -> 50000 | O7: =N7 -> 50000 | P7: =O7-P5 -> 49166.667 | Q7: =P7-Q5 -> 48333.333 | R7: =Q7-R5 -> 47500 | S7: =R7-S5 -> 46666.667 | T7: =S7-T5 -> 45833.333 | U7: =T7-U5 -> 45000 | V7: =U7-V5 -> 44166.667 | W7: =V7-W5 -> 43333.333 | ... AA7: =Z7-AA5 -> 40000 | AB7: =AA7 -> 40000 | AC7: =AB7-AC5 -> 39166.667 | AD7: =AC7-AD5 -> 38333.333 | AE7: =AD7-AE5 -> 37500 | AF7: =AE7-AF5 -> 36666.667 | AG7: =AF7-AG5 -> 35833.333 | AH7: =AG7-AH5 -> 35000 | AI7: =AH7-AI5 -> 34166.667 | AJ7: =AI7-AJ5 -> 33333.333 | ... AN7: =AM7-AN5 -> 30000 | AO7: =AN7 -> 30000 | AP7: =AO7-AP5 -> 29166.667 | AQ7: =AP7-AQ5 -> 28333.333 | AR7: =AQ7-AR5 -> 27500 | AS7: =AR7-AS5 -> 26666.667 | AT7: =AS7-AT5 -> 25833.333 | AU7: =AT7-AU5 -> 25000 | AV7: =AU7-AV5 -> 24166.667 | AW7: =AV7-AW5 -> 23333.333 | ... BA7: =AZ7-BA5 -> 20000 | BB7: =BA7 -> 20000 | BC7: =BB7-BC5 -> 19166.667 | BD7: =BC7-BD5 -> 18333.333 | BE7: =BD7-BE5 -> 17500 | BF7: =BE7-BF5 -> 16666.667 | BG7: =BF7-BG5 -> 15833.333 | BH7: =BG7-BH5 -> 15000 | BI7: =BH7-BI5 -> 14166.667 | BJ7: =BI7-BJ5 -> 13333.333 | ... BN7: =BM7-BN5 -> 10000 | BO7: =BN7 -> 10000 | BP7: =BO7-BP5 -> 9166.6667 | BQ7: =BP7-BQ5 -> 8333.3333 | BR7: =BQ7-BR5 -> 7500 | BS7: =BR7-BS5 -> 6666.6667 | BT7: =BS7-BT5 -> 5833.3333 | BU7: =BT7-BU5 -> 5000 | BV7: =BU7-BV5 -> 4166.6667 | BW7: =BV7-BW5 -> 3333.3333 | ... CA7: =BZ7-CA5 -> -5.8435035e-11 | CB7: =CA7 -> -5.8435035e-11
A9: Anuitätendahrlen Folgejahr
A10: Tilgung | B10: =B12/12/6 -> 1250 | C10: 0 | D10: 0 | E10: 0 | F10: 0 | G10: 0 | H10: 0 | I10: 0 | J10: 0 | K10: 0 | L10: 0 | M10: 0 | N10: 0 | O10: =SUM(C10:N10) -> 0 | P10: =$B$10 -> 1250 | Q10: =$B$10 -> 1250 | R10: =$B$10 -> 1250 | S10: =$B$10 -> 1250 | T10: =$B$10 -> 1250 | U10: =$B$10 -> 1250 | V10: =$B$10 -> 1250 | W10: =$B$10 -> 1250 | ... AA10: =$B$10 -> 1250 | AB10: =SUM(P10:AA10) -> 15000 | AC10: =$B$10 -> 1250 | AD10: =$B$10 -> 1250 | AE10: =$B$10 -> 1250 | AF10: =$B$10 -> 1250 | AG10: =$B$10 -> 1250 | AH10: =$B$10 -> 1250 | AI10: =$B$10 -> 1250 | AJ10: =$B$10 -> 1250 | ... AN10: =$B$10 -> 1250 | AO10: =SUM(AC10:AN10) -> 15000 | AP10: =$B$10 -> 1250 | AQ10: =$B$10 -> 1250 | AR10: =$B$10 -> 1250 | AS10: =$B$10 -> 1250 | AT10: =$B$10 -> 1250 | AU10: =$B$10 -> 1250 | AV10: =$B$10 -> 1250 | AW10: =$B$10 -> 1250 | ... BA10: =$B$10 -> 1250 | BB10: =SUM(AP10:BA10) -> 15000 | BC10: =$B$10 -> 1250 | BD10: =$B$10 -> 1250 | BE10: =$B$10 -> 1250 | BF10: =$B$10 -> 1250 | BG10: =$B$10 -> 1250 | BH10: =$B$10 -> 1250 | BI10: =$B$10 -> 1250 | BJ10: =$B$10 -> 1250 | ... BN10: =$B$10 -> 1250 | BO10: =SUM(BC10:BN10) -> 15000 | BP10: =$B$10 -> 1250 | BQ10: =$B$10 -> 1250 | BR10: =$B$10 -> 1250 | BS10: =$B$10 -> 1250 | BT10: =$B$10 -> 1250 | BU10: =$B$10 -> 1250 | BV10: =$B$10 -> 1250 | BW10: =$B$10 -> 1250 | ... CA10: =$B$10 -> 1250 | CB10: =SUM(BP10:CA10) -> 15000 | CC10: =$B$10 -> 1250 | CD10: =$B$10 -> 1250 | CE10: =$B$10 -> 1250 | CF10: =$B$10 -> 1250 | CG10: =$B$10 -> 1250 | CH10: =$B$10 -> 1250 | CI10: =$B$10 -> 1250 | CJ10: =$B$10 -> 1250 | ... CN10: =$B$10 -> 1250 | CO10: =SUM(CC10:CN10) -> 15000
A11: Zins | B11: 0.05 | C11: 0 | D11: 0 | E11: 0 | F11: 0 | G11: 0 | H11: 0 | I11: 0 | J11: 0 | K11: 0 | L11: 0 | M11: 0 | N11: 0 | O11: =SUM(C11:N11) -> 0 | P11: =B12*$B$11/12 -> 375 | Q11: =P12*$B$11/12 -> 369.79167 | R11: =Q12*$B$11/12 -> 364.58333 | S11: =R12*$B$11/12 -> 359.375 | T11: =S12*$B$11/12 -> 354.16667 | U11: =T12*$B$11/12 -> 348.95833 | V11: =U12*$B$11/12 -> 343.75 | W11: =V12*$B$11/12 -> 338.54167 | X11: =W12*$B$11/12 -> 333.33333 | ... AA11: =Z12*$B$11/12 -> 317.70833 | AB11: =SUM(P11:AA11) -> 4156.25 | AC11: =AB12*$B$11/12 -> 312.5 | AD11: =AC12*$B$11/12 -> 307.29167 | AE11: =AD12*$B$11/12 -> 302.08333 | AF11: =AE12*$B$11/12 -> 296.875 | AG11: =AF12*$B$11/12 -> 291.66667 | AH11: =AG12*$B$11/12 -> 286.45833 | AI11: =AH12*$B$11/12 -> 281.25 | AJ11: =AI12*$B$11/12 -> 276.04167 | ... AN11: =AM12*$B$11/12 -> 255.20833 | AO11: =SUM(AC11:AN11) -> 3406.25 | AP11: =AO12*$B$11/12 -> 250 | AQ11: =AP12*$B$11/12 -> 244.79167 | AR11: =AQ12*$B$11/12 -> 239.58333 | AS11: =AR12*$B$11/12 -> 234.375 | AT11: =AS12*$B$11/12 -> 229.16667 | AU11: =AT12*$B$11/12 -> 223.95833 | AV11: =AU12*$B$11/12 -> 218.75 | AW11: =AV12*$B$11/12 -> 213.54167 | ... BA11: =AZ12*$B$11/12 -> 192.70833 | BB11: =SUM(AP11:BA11) -> 2656.25 | BC11: =BB12*$B$11/12 -> 187.5 | BD11: =BC12*$B$11/12 -> 182.29167 | BE11: =BD12*$B$11/12 -> 177.08333 | BF11: =BE12*$B$11/12 -> 171.875 | BG11: =BF12*$B$11/12 -> 166.66667 | BH11: =BG12*$B$11/12 -> 161.45833 | BI11: =BH12*$B$11/12 -> 156.25 | BJ11: =BI12*$B$11/12 -> 151.04167 | ... BN11: =BM12*$B$11/12 -> 130.20833 | BO11: =SUM(BC11:BN11) -> 1906.25 | BP11: =BO12*$B$11/12 -> 125 | BQ11: =BP12*$B$11/12 -> 119.79167 | BR11: =BQ12*$B$11/12 -> 114.58333 | BS11: =BR12*$B$11/12 -> 109.375 | BT11: =BS12*$B$11/12 -> 104.16667 | BU11: =BT12*$B$11/12 -> 98.958333 | BV11: =BU12*$B$11/12 -> 93.75 | BW11: =BV12*$B$11/12 -> 88.541667 | ... CA11: =BZ12*$B$11/12 -> 67.708333 | CB11: =SUM(BP11:CA11) -> 1156.25 | CC11: =CB12*$B$11/12 -> 62.5 | CD11: =CC12*$B$11/12 -> 57.291667 | CE11: =CD12*$B$11/12 -> 52.083333 | CF11: =CE12*$B$11/12 -> 46.875 | CG11: =CF12*$B$11/12 -> 41.666667 | CH11: =CG12*$B$11/12 -> 36.458333 | CI11: =CH12*$B$11/12 -> 31.25 | CJ11: =CI12*$B$11/12 -> 26.041667 | ... CN11: =CM12*$B$11/12 -> 5.2083333 | CO11: =SUM(CC11:CN11) -> 406.25
A12: Restbetrag | B12: =Annahmen!I8 -> 90000 | C12: 0 | D12: 0 | E12: 0 | F12: 0 | G12: 0 | H12: 0 | I12: 0 | J12: 0 | K12: 0 | L12: 0 | M12: 0 | N12: 0 | O12: =SUM(C12:N12) -> 0 | P12: =B12-P10 -> 88750 | Q12: =P12-Q10 -> 87500 | R12: =Q12-R10 -> 86250 | S12: =R12-S10 -> 85000 | T12: =S12-T10 -> 83750 | U12: =T12-U10 -> 82500 | V12: =U12-V10 -> 81250 | W12: =V12-W10 -> 80000 | X12: =W12-X10 -> 78750 | ... AA12: =Z12-AA10 -> 75000 | AB12: =AA12 -> 75000 | AC12: =AB12-AC10 -> 73750 | AD12: =AC12-AD10 -> 72500 | AE12: =AD12-AE10 -> 71250 | AF12: =AE12-AF10 -> 70000 | AG12: =AF12-AG10 -> 68750 | AH12: =AG12-AH10 -> 67500 | AI12: =AH12-AI10 -> 66250 | AJ12: =AI12-AJ10 -> 65000 | ... AN12: =AM12-AN10 -> 60000 | AO12: =AN12 -> 60000 | AP12: =AO12-AP10 -> 58750 | AQ12: =AP12-AQ10 -> 57500 | AR12: =AQ12-AR10 -> 56250 | AS12: =AR12-AS10 -> 55000 | AT12: =AS12-AT10 -> 53750 | AU12: =AT12-AU10 -> 52500 | AV12: =AU12-AV10 -> 51250 | AW12: =AV12-AW10 -> 50000 | ... BA12: =AZ12-BA10 -> 45000 | BB12: =BA12 -> 45000 | BC12: =BB12-BC10 -> 43750 | BD12: =BC12-BD10 -> 42500 | BE12: =BD12-BE10 -> 41250 | BF12: =BE12-BF10 -> 40000 | BG12: =BF12-BG10 -> 38750 | BH12: =BG12-BH10 -> 37500 | BI12: =BH12-BI10 -> 36250 | BJ12: =BI12-BJ10 -> 35000 | ... BN12: =BM12-BN10 -> 30000 | BO12: =BN12 -> 30000 | BP12: =BO12-BP10 -> 28750 | BQ12: =BP12-BQ10 -> 27500 | BR12: =BQ12-BR10 -> 26250 | BS12: =BR12-BS10 -> 25000 | BT12: =BS12-BT10 -> 23750 | BU12: =BT12-BU10 -> 22500 | BV12: =BU12-BV10 -> 21250 | BW12: =BV12-BW10 -> 20000 | ... CA12: =BZ12-CA10 -> 15000 | CB12: =CA12 -> 15000 | CC12: =CB12-CC10 -> 13750 | CD12: =CC12-CD10 -> 12500 | CE12: =CD12-CE10 -> 11250 | CF12: =CE12-CF10 -> 10000 | CG12: =CF12-CG10 -> 8750 | CH12: =CG12-CH10 -> 7500 | CI12: =CH12-CI10 -> 6250 | CJ12: =CI12-CJ10 -> 5000 | ... CN12: =CM12-CN10 -> 0 | CO12: =CN12 -> 0
A14: Ratenkredit
A15: Tilgung | B15: =Annahmen!C23 -> 0 | C15: =B15 -> 0 | D15: =C15 -> 0 | E15: =D15 -> 0 | F15: =E15 -> 0 | G15: =F15 -> 0 | H15: =G15 -> 0 | I15: =H15 -> 0 | J15: =I15 -> 0 | ... N15: =M15 -> 0 | O15: =SUM(C15:N15) -> 0 | P15: =B15 -> 0 | Q15: =C15 -> 0 | R15: =D15 -> 0 | S15: =E15 -> 0 | T15: =F15 -> 0 | U15: =G15 -> 0 | V15: =H15 -> 0 | W15: =I15 -> 0 | ... AA15: =M15 -> 0 | AB15: =SUM(P15:AA15) -> 0 | AC15: =B15 -> 0 | AD15: =P15 -> 0 | AE15: =Q15 -> 0 | AF15: =R15 -> 0 | AG15: =S15 -> 0 | AH15: =T15 -> 0 | AI15: =U15 -> 0 | AJ15: =V15 -> 0 | AK15: =W15 -> 0 | ... AN15: =Z15 -> 0 | AO15: =SUM(AC15:AN15) -> 0 | AP15: =B15 -> 0 | AQ15: =AC15 -> 0 | AR15: =AD15 -> 0 | AS15: =AE15 -> 0 | AT15: =AF15 -> 0 | AU15: =AG15 -> 0 | AV15: =AH15 -> 0 | AW15: =AI15 -> 0 | AX15: =AJ15 -> 0 | ... BA15: =AM15 -> 0 | BB15: =SUM(AP15:BA15) -> 0 | BC15: =B15 -> 0 | BD15: =AP15 -> 0 | BE15: =AQ15 -> 0 | BF15: =AR15 -> 0 | BG15: =AS15 -> 0 | BH15: =AT15 -> 0 | BI15: =AU15 -> 0 | BJ15: =AV15 -> 0 | BK15: =AW15 -> 0 | ... BN15: =AZ15 -> 0 | BO15: =SUM(BC15:BN15) -> 0 | BP15: =B15 -> 0 | BQ15: =BC15 -> 0 | BR15: =BD15 -> 0 | BS15: =BE15 -> 0 | BT15: =BF15 -> 0 | BU15: =BG15 -> 0 | BV15: =BH15 -> 0 | BW15: =BI15 -> 0 | BX15: =BJ15 -> 0 | ... CA15: =BM15 -> 0 | CB15: =SUM(BP15:CA15) -> 0
A16: Zins | B16: =Annahmen!C21 -> 0.05 | C16: =B17*$B$16/12 -> 0 | D16: =C17*$B$16/12 -> 0 | E16: =D17*$B$16/12 -> 0 | F16: =E17*$B$16/12 -> 0 | G16: =F17*$B$16/12 -> 0 | H16: =G17*$B$16/12 -> 0 | I16: =H17*$B$16/12 -> 0 | J16: =I17*$B$16/12 -> 0 | ... N16: =M17*$B$16/12 -> 0 | O16: =SUM(C16:N16) -> 0 | P16: =O17*$B$16/12 -> 0 | Q16: =P17*$B$16/12 -> 0 | R16: =Q17*$B$16/12 -> 0 | S16: =R17*$B$16/12 -> 0 | T16: =S17*$B$16/12 -> 0 | U16: =T17*$B$16/12 -> 0 | V16: =U17*$B$16/12 -> 0 | W16: =V17*$B$16/12 -> 0 | ... AA16: =Z17*$B$16/12 -> 0 | AB16: =SUM(P16:AA16) -> 0 | AC16: =AB17*$B$16/12 -> 0 | AD16: =AC17*$B$16/12 -> 0 | AE16: =AD17*$B$16/12 -> 0 | AF16: =AE17*$B$16/12 -> 0 | AG16: =AF17*$B$16/12 -> 0 | AH16: =AG17*$B$16/12 -> 0 | AI16: =AH17*$B$16/12 -> 0 | AJ16: =AI17*$B$16/12 -> 0 | ... AN16: =AM17*$B$16/12 -> 0 | AO16: =SUM(AC16:AN16) -> 0 | AP16: =AO17*$B$16/12 -> 0 | AQ16: =AP17*$B$16/12 -> 0 | AR16: =AQ17*$B$16/12 -> 0 | AS16: =AR17*$B$16/12 -> 0 | AT16: =AS17*$B$16/12 -> 0 | AU16: =AT17*$B$16/12 -> 0 | AV16: =AU17*$B$16/12 -> 0 | AW16: =AV17*$B$16/12 -> 0 | ... BA16: =AZ17*$B$16/12 -> 0 | BB16: =SUM(AP16:BA16) -> 0 | BC16: =BB17*$B$16/12 -> 0 | BD16: =BC17*$B$16/12 -> 0 | BE16: =BD17*$B$16/12 -> 0 | BF16: =BE17*$B$16/12 -> 0 | BG16: =BF17*$B$16/12 -> 0 | BH16: =BG17*$B$16/12 -> 0 | BI16: =BH17*$B$16/12 -> 0 | BJ16: =BI17*$B$16/12 -> 0 | ... BN16: =BM17*$B$16/12 -> 0 | BO16: =SUM(BC16:BN16) -> 0 | BP16: =BO17*$B$16/12 -> 0 | BQ16: =BP17*$B$16/12 -> 0 | BR16: =BQ17*$B$16/12 -> 0 | BS16: =BR17*$B$16/12 -> 0 | BT16: =BS17*$B$16/12 -> 0 | BU16: =BT17*$B$16/12 -> 0 | BV16: =BU17*$B$16/12 -> 0 | BW16: =BV17*$B$16/12 -> 0 | ... CA16: =BZ17*$B$16/12 -> 0 | CB16: =SUM(BP16:CA16) -> 0
A17: Restbetrag | B17: =Annahmen!C20 -> 0 | C17: =B17-C15 -> 0 | D17: =C17-D15 -> 0 | E17: =D17-E15 -> 0 | F17: =E17-F15 -> 0 | G17: =F17-G15 -> 0 | H17: =G17-H15 -> 0 | I17: =H17-I15 -> 0 | J17: =I17-J15 -> 0 | ... N17: =M17-N15 -> 0 | O17: =N17 -> 0 | P17: =O17-P15 -> 0 | Q17: =P17-Q15 -> 0 | R17: =Q17-R15 -> 0 | S17: =R17-S15 -> 0 | T17: =S17-T15 -> 0 | U17: =T17-U15 -> 0 | V17: =U17-V15 -> 0 | W17: =V17-W15 -> 0 | ... AA17: =Z17-AA15 -> 0 | AB17: =AA17 -> 0 | AC17: =AB17-AC15 -> 0 | AD17: =AC17-AD15 -> 0 | AE17: =AD17-AE15 -> 0 | AF17: =AE17-AF15 -> 0 | AG17: =AF17-AG15 -> 0 | AH17: =AG17-AH15 -> 0 | AI17: =AH17-AI15 -> 0 | AJ17: =AI17-AJ15 -> 0 | ... AN17: =AM17-AN15 -> 0 | AO17: =AN17 -> 0 | AP17: =AO17-AP15 -> 0 | AQ17: =AP17-AQ15 -> 0 | AR17: =AQ17-AR15 -> 0 | AS17: =AR17-AS15 -> 0 | AT17: =AS17-AT15 -> 0 | AU17: =AT17-AU15 -> 0 | AV17: =AU17-AV15 -> 0 | AW17: =AV17-AW15 -> 0 | ... BA17: =AZ17-BA15 -> 0 | BB17: =BA17 -> 0 | BC17: =BB17-BC15 -> 0 | BD17: =BC17-BD15 -> 0 | BE17: =BD17-BE15 -> 0 | BF17: =BE17-BF15 -> 0 | BG17: =BF17-BG15 -> 0 | BH17: =BG17-BH15 -> 0 | BI17: =BH17-BI15 -> 0 | BJ17: =BI17-BJ15 -> 0 | ... BN17: =BM17-BN15 -> 0 | BO17: =BN17 -> 0 | BP17: =BO17-BP15 -> 0 | BQ17: =BP17-BQ15 -> 0 | BR17: =BQ17-BR15 -> 0 | BS17: =BR17-BS15 -> 0 | BT17: =BS17-BT15 -> 0 | BU17: =BT17-BU15 -> 0 | BV17: =BU17-BV15 -> 0 | BW17: =BV17-BW15 -> 0 | ... CA17: =BZ17-CA15 -> 0 | CB17: =CA17 -> 0
A19: Finanzierungskosten | C19: =C6+C16+C11 -> 250 | D19: =D6+D16+D11 -> 246.52778 | E19: =E6+E16+E11 -> 243.05556 | F19: =F6+F16+F11 -> 239.58333 | G19: =G6+G16+G11 -> 236.11111 | H19: =H6+H16+H11 -> 232.63889 | I19: =I6+I16+I11 -> 229.16667 | J19: =J6+J16+J11 -> 225.69444 | ... CB19: =CB6+CB16+CB11 -> 1427.0833
A21: Gesamt - Tilgung | C21: =C5+C15+C10 -> 833.33333 | D21: =D5+D15+D10 -> 833.33333 | E21: =E5+E15+E10 -> 833.33333 | F21: =F5+F15+F10 -> 833.33333 | G21: =G5+G15+G10 -> 833.33333 | H21: =H5+H15+H10 -> 833.33333 | I21: =I5+I15+I10 -> 833.33333 | J21: =J5+J15+J10 -> 833.33333 | ... CB21: =CB5+CB15+CB10 -> 25000
A23: Gesamt - Restbetrag Kredit | C23: =C7+C17+C12 -> 59166.667 | D23: =D7+D17+D12 -> 58333.333 | E23: =E7+E17+E12 -> 57500 | F23: =F7+F17+F12 -> 56666.667 | G23: =G7+G17+G12 -> 55833.333 | H23: =H7+H17+H12 -> 55000 | I23: =I7+I17+I12 -> 54166.667 | J23: =J7+J17+J12 -> 53333.333 | ... CB23: =CB7+CB17+CB12 -> 15000

Sheet Investitionen
A2: (in Euro) | B2: Anschaffung | C2: Kaufzeit- | D2: Nutzungdauer | E2: 2025 | Q2: Gesamt | R2: 2026 | AD2: Gesamt
B3: kosten netto | C3: punkt | D3: (in Jahren) | E3: 45658 | F3: 45689 | G3: 45717 | H3: 45748 | I3: 45778 | J3: 45809 | K3: 45839 | L3: 45870 | M3: 45901 | N3: 45931 | O3: 45962 | P3: 45992 | Q3: 2025 | R3: 46023 | S3: 46054 | T3: 46082 | U3: 46113 | V3: 46143 | W3: 46174 | X3: 46204 | Y3: 46235 | Z3: 46266 | AA3: 46296 | AB3: 46327 | AC3: 46357 | AD3: 2026
A5: Büroeinrichtung
E6: 0 | F6: 0 | G6: 0 | H6: 0 | I6: 0 | J6: 0 | K6: 0 | L6: 0 | M6: 0 | N6: 0 | O6: 0 | P6: 0 | Q6: - | R6: 0 | S6: 0 | T6: 0 | U6: 0 | V6: 0 | W6: 0 | X6: 0 | Y6: 0 | Z6: 0 | AA6: 0 | AB6: 0 | AC6: 0 | AD6: 0
A7: Arbeitsplatzeinrichtung | B7: =Annahmen!E68 -> 65000 | C7: =Annahmen!D68 -> 45658 | D7: =Annahmen!B69 -> 13 | E7: =$Q$7/12 -> 416.66667 | F7: =$Q$7/12 -> 416.66667 | G7: =$Q$7/12 -> 416.66667 | H7: =$Q$7/12 -> 416.66667 | I7: =$Q$7/12 -> 416.66667 | J7: =$Q$7/12 -> 416.66667 | K7: =$Q$7/12 -> 416.66667 | L7: =$Q$7/12 -> 416.66667 | ... P7: =$Q$7/12 -> 416.66667 | Q7: =$B$7/$D$7 -> 5000 | R7: =$AD$7/12 -> 416.66667 | S7: =$AD$7/12 -> 416.66667 | T7: =$AD$7/12 -> 416.66667 | U7: =$AD$7/12 -> 416.66667 | V7: =$AD$7/12 -> 416.66667 | W7: =$AD$7/12 -> 416.66667 | X7: =$AD$7/12 -> 416.66667 | Y7: =$AD$7/12 -> 416.66667 | ... AC7: =$AD$7/12 -> 416.66667 | AD7: =$B$7/$D$7 -> 5000
E8: - | F8: - | G8: - | H8: - | I8: - | J8: - | K8: - | L8: - | M8: - | N8: - | O8: - | P8: - | Q8: - | R8: 0 | S8: 0 | T8: 0 | U8: 0 | V8: 0 | W8: 0 | X8: 0 | Y8: 0 | Z8: 0 | AA8: 0 | AB8: 0 | AC8: 0 | AD8: 0
A9: Gesamtabschreibung - Büroeinrichtung | E9: =SUM(E6:E8) -> 416.66667 | F9: =SUM(F6:F8) -> 416.66667 | G9: =SUM(G6:G8) -> 416.66667 | H9: =SUM(H6:H8) -> 416.66667 | I9: =SUM(I6:I8) -> 416.66667 | J9: =SUM(J6:J8) -> 416.66667 | K9: =SUM(K6:K8) -> 416.66667 | L9: =SUM(L6:L8) -> 416.66667 | ... Q9: =SUM(Q6:Q8) -> 5000 | R9: =R7 -> 416.66667 | S9: =S7 -> 416.66667 | T9: =T7 -> 416.66667 | U9: =U7 -> 416.66667 | V9: =V7 -> 416.66667 | W9: =W7 -> 416.66667 | X9: =X7 -> 416.66667 | Y9: =Y7 -> 416.66667 | ... AD9: =AD7 -> 5000
A10: Gesamtinvestitionen - Büroeinrichtung | E10: =B7 -> 65000 | F10: 0 | G10: 0 | H10: 0 | I10: 0 | J10: 0 | K10: 0 | L10: 0 | M10: 0 | N10: 0 | O10: 0 | P10: 0 | Q10: {=E10:P10} -> 65000 | R10: 0 | S10: 0 | T10: 0 | U10: 0 | V10: 0 | W10: 0 | X10: 0 | Y10: 0 | Z10: 0 | AA10: 0 | AB10: 0 | AC10: 0 | AD10: 0
A11: EDV
E12: 0 | F12: 0 | G12: 0 | H12: 0 | I12: 0 | J12: 0 | K12: 0 | L12: 0 | M12: 0 | N12: 0 | O12: 0 | P12: 0 | Q12: 0 | R12: 0 | S12: 0 | T12: 0 | U12: 0 | V12: 0 | W12: 0 | X12: 0 | Y12: 0 | Z12: 0 | AA12: 0 | AB12: 0 | AC12: 0 | AD12: 0
A13: PCs. Laptops etc. | B13: =Annahmen!E65 -> 39000 | C13: =Annahmen!D65 -> 45658 | D13: =Annahmen!B66 -> 3 | E13: =$Q$13/12 -> 1083.3333 | F13: =$Q$13/12 -> 1083.3333 | G13: =$Q$13/12 -> 1083.3333 | H13: =$Q$13/12 -> 1083.3333 | I13: =$Q$13/12 -> 1083.3333 | J13: =$Q$13/12 -> 1083.3333 | K13: =$Q$13/12 -> 1083.3333 | L13: =$Q$13/12 -> 1083.3333 | ... P13: =$Q$13/12 -> 1083.3333 | Q13: =$B$13/$D$13 -> 13000 | R13: =$AD$13/12 -> 1083.3333 | S13: =$AD$13/12 -> 1083.3333 | T13: =$AD$13/12 -> 1083.3333 | U13: =$AD$13/12 -> 1083.3333 | V13: =$AD$13/12 -> 1083.3333 | W13: =$AD$13/12 -> 1083.3333 | X13: =$AD$13/12 -> 1083.3333 | Y13: =$AD$13/12 -> 1083.3333 | ... AC13: =$AD$13/12 -> 1083.3333 | AD13: =$B$13/$D$13 -> 13000
A14: Server etc. | B14: =Annahmen!F71 -> 30000 | C14: =Annahmen!D71 -> 46023 | D14: =Annahmen!B72 -> 5 | E14: 0 | F14: 0 | G14: 0 | H14: 0 | I14: 0 | J14: 0 | K14: 0 | L14: 0 | M14: 0 | N14: 0 | O14: 0 | P14: 0 | Q14: 0 | R14: =$AD$14/12 -> 500 | S14: =$AD$14/12 -> 500 | T14: =$AD$14/12 -> 500 | U14: =$AD$14/12 -> 500 | V14: =$AD$14/12 -> 500 | W14: =$AD$14/12 -> 500 | X14: =$AD$14/12 -> 500 | Y14: =$AD$14/12 -> 500 | ... AC14: =$AD$14/12 -> 500 | AD14: =B14/D14 -> 6000
E15: 0 | F15: 0 | G15: 0 | H15: 0 | I15: 0 | J15: 0 | K15: 0 | L15: 0 | M15: 0 | N15: 0 | O15: 0 | P15: 0 | Q15: 0 | R15: 0 | S15: 0 | T15: 0 | U15: 0 | V15: 0 | W15: 0 | X15: 0 | Y15: 0 | Z15: 0 | AA15: 0 | AB15: 0 | AC15: 0 | AD15: 0
A16: Gesamtabschreibung - EDV | E16: =SUM(E13:E14) -> 1083.3333 | F16: =SUM(F13:F14) -> 1083.3333 | G16: =SUM(G13:G14) -> 1083.3333 | H16: =SUM(H13:H14) -> 1083.3333 | I16: =SUM(I13:I14) -> 1083.3333 | J16: =SUM(J13:J14) -> 1083.3333 | K16: =SUM(K13:K14) -> 1083.3333 | L16: =SUM(L13:L14) -> 1083.3333 | ... AD16: =SUM(AD13:AD14) -> 19000
A17: Gesamtinvestitionen - EDV | E17: =B13 -> 39000 | F17: 0 | G17: 0 | H17: 0 | I17: 0 | J17: 0 | K17: 0 | L17: 0 | M17: 0 | N17: 0 | O17: 0 | P17: 0 | Q17: =SUM(E17:P17) -> 39000 | R17: =B14 -> 30000 | S17: 0 | T17: 0 | U17: 0 | V17: 0 | W17: 0 | X17: 0 | Y17: 0 | Z17: 0 | AA17: 0 | AB17: 0 | AC17: 0 | AD17: =SUM(R17:AC17) -> 30000
A19: Gesamt Abschreibung | E19: =E9+E16 -> 1500 | F19: =F9+F16 -> 1500 | G19: =G9+G16 -> 1500 | H19: =H9+H16 -> 1500 | I19: =I9+I16 -> 1500 | J19: =J9+J16 -> 1500 | K19: =K9+K16 -> 1500 | L19: =L9+L16 -> 1500 | ... AD19: =AD9+AD16 -> 24000
A20: Gesamt Investition | E20: =SUM(E10+E17) -> 104000 | F20: =SUM(F10+F17) -> 0 | G20: =SUM(G10+G17) -> 0 | H20: =SUM(H10+H17) -> 0 | I20: =SUM(I10+I17) -> 0 | J20: =SUM(J10+J17) -> 0 | K20: =SUM(K10+K17) -> 0 | L20: =SUM(L10+L17) -> 0 | ... AD20: =SUM(AD10+AD17) -> 30000
